<?xml version="1.0"?>
<!--
Software License Agreement (BSD)

\file      husky.urdf.xacro
\authors   Paul Bovbel <pbovbel@clearpathrobotics.com>, Devon Ash <dash@clearpathrobotics.com>
\copyright Copyright (c) 2015, Clearpath Robotics, Inc., All rights reserved.

Redistribution and use in source and binary forms, with or without modification, are permitted provided that
the following conditions are met:
 * Redistributions of source code must retain the above copyright notice, this list of conditions and the
   following disclaimer.
 * Redistributions in binary form must reproduce the above copyright notice, this list of conditions and the
   following disclaimer in the documentation and/or other materials provided with the distribution.
 * Neither the name of Clearpath Robotics nor the names of its contributors may be used to endorse or promote
   products derived from this software without specific prior written permission.

THIS SOFTWARE IS PROVIDED BY THE COPYRIGHT HOLDERS AND CONTRIBUTORS "AS IS" AND ANY EXPRESS OR IMPLIED WAR-
RANTIES, INCLUDING, BUT NOT LIMITED TO, THE IMPLIED WARRANTIES OF MERCHANTABILITY AND FITNESS FOR A PARTICULAR
PURPOSE ARE DISCLAIMED. IN NO EVENT SHALL THE COPYRIGHT HOLDER OR CONTRIBUTORS BE LIABLE FOR ANY DIRECT, IN-
DIRECT, INCIDENTAL, SPECIAL, EXEMPLARY, OR CONSEQUENTIAL DAMAGES (INCLUDING, BUT NOT LIMITED TO, PROCUREMENT
OF SUBSTITUTE GOODS OR SERVICES; LOSS OF USE, DATA, OR PROFITS; OR BUSINESS INTERRUPTION) HOWEVER CAUSED AND
ON ANY THEORY OF LIABILITY, WHETHER IN CONTRACT, STRICT LIABILITY, OR TORT (INCLUDING NEGLIGENCE OR OTHERWISE)
ARISING IN ANY WAY OUT OF THE USE OF THIS SOFTWARE, EVEN IF ADVISED OF THE POSSIBILITY OF SUCH DAMAGE.
-->
<robot name="husky_robot" xmlns:xacro="http://ros.org/wiki/xacro">


  <property name="M_PI" value="3.14159"/>

  <!-- Base Size -->
  <property name="base_x_size" value="0.98740000" />
  <property name="base_y_size" value="0.57090000" />
  <property name="base_z_size" value="0.24750000" />

  <!-- Wheel Mounting Positions -->
  <xacro:property name="wheelbase" value="0.5120" />
  <xacro:property name="track" value="0.5708" />
  <xacro:property name="wheel_vertical_offset" value="0.03282" />

  <!-- Wheel Properties -->
  <xacro:property name="wheel_length" value="0.1143" />
  <xacro:property name="wheel_radius" value="0.17775" />


<!-- POWERCUBES -->

    <property name="base_cube_origin_x" value=".1" />
    <property name="base_cube_origin_y" value=".15" />
    <property name="base_cube_origin_z" value=".4" />
        
<!-- Angle connector -->
    <link name="base_link">
        <inertial>
            <mass value="0.0001" />
            <origin xyz="0 0 0" />
            <inertia ixx="0.0001" ixy="0.0" ixz="0.0"
                iyy="0.0001" iyz="0.0" 
                izz="0.0001" />
        </inertial>

        <visual>
            <origin xyz="0 0 .1" rpy="0 ${M_PI/2} ${M_PI}" />
            <geometry>
                <mesh filename="package://husky_description/meshes/cubefinal.stl" />
            </geometry>
            <material name="DarkPCubeGrey" >
		<color rgba=".1 .1 .1 1" />
    	    </material>
        </visual>
    </link>

<!-- FIXED-CUBE-5 -->
    <link name="fixed_cube_5">
        <inertial>
            <mass value="0.0001" />
            <origin xyz="0 0 0" />
            <inertia ixx="0.0001" ixy="0.0" ixz="0.0"
                iyy="0.0001" iyz="0.0" 
                izz="0.0001" />
        </inertial>

        <visual>
            <origin xyz="0 0 0" rpy="0 0 0" />
            <geometry>
                <box size="0.07 0.07 0.07" />
            </geometry>
            <material name="PCubeGrey" >
		<color rgba=".2 .2 .2 1" />
    	    </material>
        </visual>
    </link>

    <joint name="fixed_cube_5_joint" type="fixed">
		<origin xyz="0.035 -0.035 0.065" rpy="0 0 0" />
        <parent link="base_link"/>
        <child link="fixed_cube_5" />
    </joint>
 <!-- CUBE-5 -->
    <link name="cube_5">
        <inertial>
            <mass value="0.0001" />
            <origin xyz="0 0 0" />
            <inertia ixx="0.0001" ixy="0.0" ixz="0.0"
                iyy="0.0001" iyz="0.0" 
                izz="0.0001" />
        </inertial>

        <visual>
            <origin xyz="0 0 0" rpy="0 0 0" />
            <geometry>
                <box size="0.07 0.07 0.07" />
            </geometry>
            <material name="PCubeGrey" >
		<color rgba=".2 .2 .2 1" />
    	    </material>
        </visual>
    </link>

    <joint name="cube_5_joint" type="continuous">
		<origin xyz="0 -0.07 0" rpy="0 -${M_PI/2} 0" />
	  <axis xyz="0 -1 0" />
        <parent link="fixed_cube_5"/>
        <child link="cube_5" />
    </joint>

  <!-- LASER payload (by default, a SICK LMS111). -->
  
    <link name="laser">
      <visual>
        <origin xyz="0 0 0" rpy="0 0 0" />
        <geometry>
          <mesh filename="package://husky_description/meshes/sick_lms1xx.dae" />
        </geometry>
        <material name="dark_grey" />
      </visual>
    </link>

    <joint name="laser_mount_joint" type="fixed">
      <origin xyz="0.094 -0.029 0.0075" rpy="0 0 0" />
      <parent link="cube_5" />
      <child link="laser" />
    </joint>



</robot>
